Workbook

Sheet Bilgi
A1: Amaç | B1: TCMB döviz çıkış istatistik kodlarının (kaynak: İstatistik Kod Bazlı Kategori sayfası, F sütunu) Katar Merkez Bankası Purpose of Payment (PoP) kodları ile eşleştirilmesi.
A2: Yön mantığı | B2: İstatistik kodları Türkiye'den yurt dışına ÇIKIŞ işlemleridir. Ödeme Katar'a gittiğinde Katar tarafında GELEN ödeme olur; bu yüzden QAR listesindeki 'A' (receipt/inward) kodları ile eşleştirilmiştir. Örn: ithalat ödemesi (TR) → ihracat tahsilatı (QAR).
A3: Eşleştirme formatı | B3: İstatistikKodu-QARKodu (örn. 5807-A2J02). A sütunu formülle üretilir; D sütunundaki QAR kodu değiştirilirse A ve E sütunları otomatik güncellenir (D sütununda açılır liste vardır).
A4: Eşleşme Derecesi | B4: Tam: anlam birebir örtüşüyor. Yakın: ana amaç örtüşüyor, kapsam/taraf farkı var. Genel / En yakın: QAR listesinde karşılığı yok, en uygun genel kod seçildi — operasyon/uyum ekibi teyit etmeli.
A5: Mükerrer kodlar | B5: Kaynakta birden fazla kategoride geçen kodlar (örn. 5446, 5447, 7500) tek satırda birleştirildi; tüm kategoriler H sütununda listelenmiştir.
A6: Kapsam | B6: 281 benzersiz istatistik kodu, 85 QAR PoP kodu. Aynı QAR kodu birden fazla istatistik koduna karşılık gelebilir ('QAR Kodları' sayfasında sayısı görülebilir).
A7: Uyarı | B7: Eşleştirme, açıklama metinlerine göre yapılmış bir öneridir. Katar'daki muhabir/alıcı bankanın kendi kural setiyle canlı kullanım öncesi teyit edilmesi önerilir.

Sheet Eşleştirme
A1: Eşleştirme (İst. Kodu-QAR) | B1: İstatistik Kodu | C1: İstatistik Kod Açıklaması (TR) | D1: QAR PoP Kodu | E1: QAR Purpose of Payment Narration (EN) | F1: Eşleşme Derecesi | G1: Not / Gerekçe | H1: TCMB Ödeme Kategorisi
A2: =B2&"-"&D2 -> 5120-A1A01 | B2: 5120 | C2: Yurtiçinde yerleşik kişilere ait deniz, hava ve kara taşıtlarına yurt limanlarda sağlanan yakıt ve kumanya bedeli (Deniz taşıtlarına ilişkin olarak, bir gemi işletmecisinin birçok farklı ülkede kayıtlı gemisi bulunabilmektedir. Gemi işletmecilerinin yerleşikliğinin tespit edilmesinde, gemilerdeki elverişli bayrak - gemi sahibinin gemisine kendi ülkesinin bayrağı yerine çeşitli kolaylıklar gösteren bir başka devletin bayrağını çekmesi - kullanılmamalıdır. Yerleşiklik için gemicilik faaliyetini yürüten işletmenin bulunduğu ülke esas alınmalıdır.) | D2: A1A01 | E2: =IFERROR(INDEX('QAR Kodları'!$B:$B,MATCH(D2,'QAR Kodları'!$A:$A,0)),"KOD BULUNAMADI") -> Value of export bills negotiated/purchased/discounted etc | F2: Genel / En yakın | G2: Limanlarda sağlanan yakıt/kumanya (mal niteliğinde). | H2: 30) Taşımacılık ve lojistik hizmetleri
A3: =B3&"-"&D3 -> 5445-A1A01 | B3: 5445 | C3: Leasing kontratına bağlı olarak ödenen ithalat mal F.O.B. bedeli (Navlun ve sigorta hariç) | D3: A1A01 | E3: =IFERROR(INDEX('QAR Kodları'!$B:$B,MATCH(D3,'QAR Kodları'!$A:$A,0)),"KOD BULUNAMADI") -> Value of export bills negotiated/purchased/discounted etc | F3: Yakın | G3: Leasing'e bağlı ithalat mal bedeli. | H3: 9) İthalat/İhracat Ödemesi İşlemleri (Gümrük Komisyonları Dahil)
A4: =B4&"-"&D4 -> 5446-A1A02 | B4: 5446 | C4: 1996 yıl başından itibaren başlayan, Kabul Kredili Mal Mukabili ve Mal Mukabili İthalat işlemleri nedeniyle yapılan FOB ithalat ödemeleri (Navlun ve sigorta hariç) | D4: A1A02 | E4: =IFERROR(INDEX('QAR Kodları'!$B:$B,MATCH(D4,'QAR Kodları'!$A:$A,0)),"KOD BULUNAMADI") -> Realization of export bills (in respect of goods) sent on collection (full invoice value) | F4: Tam | G4: Mal mukabili / vesaik mukabili tahsil. | H4: 9) İthalat/İhracat Ödemesi İşlemleri (Gümrük Komisyonları Dahil); 38) Kıymetli maden ithalat ödemesi
A5: =B5&"-"&D5 -> 5447-A1A03 | B5: 5447 | C5: Peşin ödeme ile yapılan ithalat mal F.O.B. bedeli (Navlun ve sigorta hariç) | D5: A1A03 | E5: =IFERROR(INDEX('QAR Kodları'!$B:$B,MATCH(D5,'QAR Kodları'!$A:$A,0)),"KOD BULUNAMADI") -> Advance receipts against export contracts (export of goods only) | F5: Tam | G5: Peşin ödeme = ihracat sözleşmesine karşı avans tahsili. | H5: 9) İthalat/İhracat Ödemesi İşlemleri (Gümrük Komisyonları Dahil); 38) Kıymetli maden ithalat ödemesi
A6: =B6&"-"&D6 -> 5448-A1A01 | B6: 5448 | C6: Yurtiçinde yerleşik diğer bir bankada başlayan ithalat işlemleri sonucunda oluşan kısa vadeli ithalat borçlarına ilişkin ödenen ithalat mal F.O.B. bedeli (Navlun ve sigorta hariç) | D6: A1A01 | E6: =IFERROR(INDEX('QAR Kodları'!$B:$B,MATCH(D6,'QAR Kodları'!$A:$A,0)),"KOD BULUNAMADI") -> Value of export bills negotiated/purchased/discounted etc | F6: Yakın | G6: Başka bankada başlayan ithalatın borç ödemesi. | H6: 9) İthalat/İhracat Ödemesi İşlemleri (Gümrük Komisyonları Dahil); 38) Kıymetli maden ithalat ödemesi
A7: =B7&"-"&D7 -> 5700-A2A04 | B7: 5700 | C7: İhracat navlunu (DENİZ): Yurtiçinde yerleşik kişiler tarafından yurtdışında yerleşik kişilere Türkiye'den yurtdışına yapılan ihracat nedeniyle ödenen navlun bedelleri | D7: A2A04 | E7: =IFERROR(INDEX('QAR Kodları'!$B:$B,MATCH(D7,'QAR Kodları'!$A:$A,0)),"KOD BULUNAMADI") -> Freight on exports-shipping companies | F7: Tam | G7: Deniz navlunu. | H7: 30) Taşımacılık ve lojistik hizmetleri
A8: =B8&"-"&D8 -> 5701-A2A04 | B8: 5701 | C8: İthalat navlunu: Yurtiçinde yerleşik kişiler tarafından yurtdışında yerleşik kişilere Türkiye'ye yapılan ithalat nedeniyle ödenen navlun bedelleri | D8: A2A04 | E8: =IFERROR(INDEX('QAR Kodları'!$B:$B,MATCH(D8,'QAR Kodları'!$A:$A,0)),"KOD BULUNAMADI") -> Freight on exports-shipping companies | F8: Tam | G8: Deniz navlunu. | H8: 30) Taşımacılık ve lojistik hizmetleri
A9: =B9&"-"&D9 -> 5702-A2A04 | B9: 5702 | C9: Transit taşımacılık navlunu (DENİZ): Yurtiçinde yerleşik kişiler tarafından transit olarak yapılan mal nakliyatı nedeniyle yurtdışında yerleşik kişilere ödenen navlun bedelleri | D9: A2A04 | E9: =IFERROR(INDEX('QAR Kodları'!$B:$B,MATCH(D9,'QAR Kodları'!$A:$A,0)),"KOD BULUNAMADI") -> Freight on exports-shipping companies | F9: Tam | G9: Deniz navlunu. | H9: 30) Taşımacılık ve lojistik hizmetleri
A10: =B10&"-"&D10 -> 5703-A2A01 | B10: 5703 | C10: Uluslararası yolcu taşımacılığı (DENİZ): Yurtdışında yerleşik kişiler tarafından yurtiçinde yerleşik kişilere sağlanan yolcu bileti, fazla bagaj gibi taşımacılık hizmetleri ile yurtiçinde yerleşik kişilere mürettebatıyla birlikte kısa süreli taşıt kiralanması nedeniyle ödenen bedeller | D10: A2A01 | E10: =IFERROR(INDEX('QAR Kodları'!$B:$B,MATCH(D10,'QAR Kodları'!$A:$A,0)),"KOD BULUNAMADI") -> Inward remittance on account of surplus freight/passenger fare by Qatari shipping companies operating abroad | F10: Yakın | G10: Deniz yolcu taşımacılığı. Mürettebatlı kiralama ise A2A05. | H10: 30) Taşımacılık ve lojistik hizmetleri
A11: =B11&"-"&D11 -> 5704-A2A13 | B11: 5704 | C11: Diğer taşımacılık hizmetleri (DENİZ): Yurtiçinde yerleşik kişilere yurtdışı limanlarda sağlanan kargo yükleme/boşaltma, depolama, temizleme, çekme, kurtarma vb. hizmetleri ile yurtiçindeki liman, havalimanı, tren istasyonu, terminal gibi tesislerin işletilmesi nedeniyle yurtdışında yerleşik kişilere ödenen bedeller | D11: A2A13 | E11: =IFERROR(INDEX('QAR Kodları'!$B:$B,MATCH(D11,'QAR Kodları'!$A:$A,0)),"KOD BULUNAMADI") -> Receipts towards other transportation services (stevedoring demurrage port handling charges etc | F11: Tam | G11: Liman hizmetleri, yükleme-boşaltma vb. | H11: 30) Taşımacılık ve lojistik hizmetleri
A12: =B12&"-"&D12 -> 5705-A2A10 | B12: 5705 | C12: İhracat navlunu (HAVA) : Yurtiçinde yerleşik kişiler tarafından yurtdışında yerleşik kişilere Türkiye'den yurtdışına yapılan ihracat nedeniyle ödenen navlun bedelleri | D12: A2A10 | E12: =IFERROR(INDEX('QAR Kodları'!$B:$B,MATCH(D12,'QAR Kodları'!$A:$A,0)),"KOD BULUNAMADI") -> Freight on exports-airlines companies | F12: Tam | G12: Hava navlunu. | H12: 30) Taşımacılık ve lojistik hizmetleri
A13: =B13&"-"&D13 -> 5706-A2A10 | B13: 5706 | C13: İthalat navlunu: Yurtiçinde yerleşik kişiler tarafından yurtdışında yerleşik kişilere Türkiye'ye yapılan ithalat nedeniyle ödenen navlun bedelleri | D13: A2A10 | E13: =IFERROR(INDEX('QAR Kodları'!$B:$B,MATCH(D13,'QAR Kodları'!$A:$A,0)),"KOD BULUNAMADI") -> Freight on exports-airlines companies | F13: Tam | G13: Hava navlunu. | H13: 30) Taşımacılık ve lojistik hizmetleri
... A28: =B28&"-"&D28 -> 5721-A2K02 | B28: 5721 | C28: Posta ve Kurye Hizmetleri Yurtdışında yerleşik kişiler tarafından yurtiçinde yerleşik kişilere sağlanan posta ve kurye hizmetleri nedeniyle ödenen bedeller | D28: A2K02 | E28: =IFERROR(INDEX('QAR Kodları'!$B:$B,MATCH(D28,'QAR Kodları'!$A:$A,0)),"KOD BULUNAMADI") -> Receipts on account of settlement of claims for courier services | F28: Yakın | G28: Kurye hizmetleri. Posta ise A2K01. | H28: 30) Taşımacılık ve lojistik hizmetleri
A29: =B29&"-"&D29 -> 5730-A2B01 | B29: 5730 | C29: Seyahat giderleri-Kurs-Kongre-Tatil-Eğitim-Tedavi-Hac (Tesis edilen seyahat çek bedelleri de muhabire borç kaydedildiği zaman bu kod altında bildirilecektir) | D29: A2B01 | E29: =IFERROR(INDEX('QAR Kodları'!$B:$B,MATCH(D29,'QAR Kodları'!$A:$A,0)),"KOD BULUNAMADI") -> Inward remittance towards business travel includes purchases of foreign tcs,currency notes etc. Over the counter by hotels,hospitals,emporium | F29: Tam | H29: 34) Seyahat, turizm, eğitim ve sağlık hizmetleri
A30: =B30&"-"&D30 -> 5740-A2D01 | B30: 5740 | C30: Yurtdışında gerçekleştirilen inşaat hizmetleri giderleri: Yurtiçinde yerleşik kişiler tarafından yurtdışında gerçekleştirilen inşaat hizmetleri ile ilgili olarak, yurtdışında yerleşik kişilerden sağlanan mal ve hizmetler nedeniyle ödenen bedeller (Hazırlık avansları dahil) | D30: A2D01 | E30: =IFERROR(INDEX('QAR Kodları'!$B:$B,MATCH(D30,'QAR Kodları'!$A:$A,0)),"KOD BULUNAMADI") -> Inward remittance towards meeting the cost of construction of projects in Qatar | F30: Tam | G30: Katar'da gerçekleştirilen inşaat projesi giderleri. | H30: 28) Ticaret ve endüstri hizmetleri
A31: =B31&"-"&D31 -> 5741-A2D01 | B31: 5741 | C31: Yurtiçinde gerçekleştirilen inşaat hizmetleri giderleri: Yurtdışında yerleşik kişiler tarafından yurtiçinde gerçekleştirilen inşaat hizmetleri nedeniyle ödenen bedeller | D31: A2D01 | E31: =IFERROR(INDEX('QAR Kodları'!$B:$B,MATCH(D31,'QAR Kodları'!$A:$A,0)),"KOD BULUNAMADI") -> Inward remittance towards meeting the cost of construction of projects in Qatar | F31: Genel / En yakın | G31: Türkiye'de yabancı müteahhit inşaat bedeli; QAR'da yurt dışı inşaat ayrımı yok. | H31: 28) Ticaret ve endüstri hizmetleri
A32: =B32&"-"&D32 -> 5750-A2C01 | B32: 5750 | C32: Hayat sigortası: Yurtiçinde yerleşik gerçek kişiler tarafından yurtdışında yerleşik sigorta şirketlerine yapılan prim ödemeleri ile yurtiçinde yerleşik sigorta şirketlerinin hayat sigortası ile ilgili olarak yurtdışında yerleşik gerçek kişilere yaptıkları ödemeler (Ölüme bağlı hayat sigortasına ilişkin bedeller hariç tutulacaktır) | D32: A2C01 | E32: =IFERROR(INDEX('QAR Kodları'!$B:$B,MATCH(D32,'QAR Kodları'!$A:$A,0)),"KOD BULUNAMADI") -> Receipts on account of life insurance premium | F32: Tam | H32: 31) Sigorta ve reasürans hizmetleri
A33: =B33&"-"&D33 -> 5751-A2C01 | B33: 5751 | C33: Emeklilik hizmetleri: Yurtiçinde yerleşik gerçek kişiler tarafından yurtdışında yerleşik sigorta şirketlerine yapılan prim ödemeleri ile yurtiçinde yerleşik sigorta şirketlerinin emeklilik hizmetleri ile ilgili olarak yurtdışında yerleşik gerçek kişilere yaptıkları ödemeler | D33: A2C01 | E33: =IFERROR(INDEX('QAR Kodları'!$B:$B,MATCH(D33,'QAR Kodları'!$A:$A,0)),"KOD BULUNAMADI") -> Receipts on account of life insurance premium | F33: Genel / En yakın | G33: Emeklilik hizmetleri; QAR'da ayrı kod yok. | H33: 35) Kişisel gelir ve harcamalar, ücret ve emeklilik ödemeleri
A34: =B34&"-"&D34 -> 5752-A2C02 | B34: 5752 | C34: Navlun sigortası: Yurtiçinde yerleşik kişilerin mal taşımacılığı alanında aldıkları sigortacılık hizmetlerinden dolayı yurtdışında yerleşik sigorta şirketlerine ödedikleri primler ile yurtiçinde yerleşik sigorta şirketlerinin bu kapsamda yurtdışında yerleşik kişilere yaptıkları tazminat ödemeleri | D34: A2C02 | E34: =IFERROR(INDEX('QAR Kodları'!$B:$B,MATCH(D34,'QAR Kodları'!$A:$A,0)),"KOD BULUNAMADI") -> Receipts on account of freight insurance relating to import & export goods | F34: Tam | H34: 31) Sigorta ve reasürans hizmetleri
A35: =B35&"-"&D35 -> 5753-A2C03 | B35: 5753 | C35: Diğer doğrudan sigorta: Yurtiçinde yerleşik kişilerin, hayat, emeklilik ve navlun sigortası dışındaki ölüme bağlı hayat sigortası, özel sağlık sigortası ile kaza, yangın, doğal afet, seyahat, kredi kartı sigortası gibi alanlarda aldıkları sigortacılık hizmetlerinden dolayı yurtdışında yerleşik sigorta şirketlerine ödedikleri primler ile yurtiçinde yerleşik sigorta şirketlerinin bu kapsamda yurtdışında yerleşik gerçek kişilere yaptıkları tazminat ödemeleri (Ölüme bağlı hayat sigortasına ilişkin bedeller bu kod altında bildirilecektir.) | D35: A2C03 | E35: =IFERROR(INDEX('QAR Kodları'!$B:$B,MATCH(D35,'QAR Kodları'!$A:$A,0)),"KOD BULUNAMADI") -> Receipts of other general insurance premium | F35: Tam | H35: 31) Sigorta ve reasürans hizmetleri
A36: =B36&"-"&D36 -> 5754-A2C04 | B36: 5754 | C36: Reasürans: Yurtiçinde yerleşik reasürörlerin, yurtdışında yerleşik sedan şirketlerine yaptıkları hasar ödemeleri ile yurtiçinde yerleşik sedan şirketlerinin reasürans nedeniyle yurtdışında yerleşik reasürörlere devrettikleri primler | D36: A2C04 | E36: =IFERROR(INDEX('QAR Kodları'!$B:$B,MATCH(D36,'QAR Kodları'!$A:$A,0)),"KOD BULUNAMADI") -> Receipts on account of reinsurance premium | F36: Tam | H36: 31) Sigorta ve reasürans hizmetleri
A37: =B37&"-"&D37 -> 5755-A2C03 | B37: 5755 | C37: Standartlaştırılmış garanti hizmetleri: Yurtiçinde yerleşik kişiler tarafından yurtdışında yerleşik sigorta şirketlerine garantör hizmetleri, ihracat kredi garantisi vb. için yapılan prim ödemeleri ile yurtiçinde yerleşik sigorta şirketlerinin bu kapsamda yurtdışında yerleşik kişilere yaptıkları tazminat ödemeleri | D37: A2C03 | E37: =IFERROR(INDEX('QAR Kodları'!$B:$B,MATCH(D37,'QAR Kodları'!$A:$A,0)),"KOD BULUNAMADI") -> Receipts of other general insurance premium | F37: Yakın | G37: Standart garanti hizmetleri (ihracat kredi garantisi vb.). | H37: 31) Sigorta ve reasürans hizmetleri
A38: =B38&"-"&D38 -> 5756-A2C05 | B38: 5756 | C38: Sigortacılık yardımcı hizmetleri: Yurtiçinde yerleşik kişilerin, her türlü sigorta işlemleri nedeniyle yurtdışında yerleşik kişilere ödedikleri acente komisyonu, danışmanlık hizmet bedelleri ve benzeri giderler | D38: A2C05 | E38: =IFERROR(INDEX('QAR Kodları'!$B:$B,MATCH(D38,'QAR Kodları'!$A:$A,0)),"KOD BULUNAMADI") -> Receipts on account of auxiliary services (commission on insurance) | F38: Tam | H38: 31) Sigorta ve reasürans hizmetleri
A39: =B39&"-"&D39 -> 5760-A2F01 | B39: 5760 | C39: Yurtdışında yerleşik kişilerden alınan finansal aracılık ve finansal nitelikli danışmanlık, saklama ve varlık yönetimi gibi hizmetler nedeniyle ödenen her türlü hizmet komisyonu ve benzeri giderler | D39: A2F01 | E39: =IFERROR(INDEX('QAR Kodları'!$B:$B,MATCH(D39,'QAR Kodları'!$A:$A,0)),"KOD BULUNAMADI") -> Receipts on account of financial intermediation except investment banking-bank charges, collection charges,lc charges, cancellation of forward | F39: Tam | G39: Finansal aracılık ücret/komisyonu. Saklama/varlık yönetimi ise A2F03. | H39: 23) Bankacılık ve finansal hizmetlerle ilgili Ücret, masraf, komisyon ödemeleri
A40: =B40&"-"&D40 -> 5761-A2F02 | B40: 5761 | C40: Yurtdışında yerleşik kişilerden finansal türev işlemleri ile ilgili alınan aracılık hizmetleri nedeniyle ödenen her türlü hizmet komisyonu ve benzeri giderler | D40: A2F02 | E40: =IFERROR(INDEX('QAR Kodları'!$B:$B,MATCH(D40,'QAR Kodları'!$A:$A,0)),"KOD BULUNAMADI") -> Receipts on account of investment banking services-brokerage, under writing commission etc | F40: Tam | G40: Türev işlem aracılık komisyonu. | H40: 23) Bankacılık ve finansal hizmetlerle ilgili Ücret, masraf, komisyon ödemeleri
A41: =B41&"-"&D41 -> 5762-A2F01 | B41: 5762 | C41: Yurtiçinde yerleşik kişilerden alınan finansal aracılık ve finansal nitelikli danışmanlık, saklama ve varlık yönetimi gibi hizmetler nedeniyle ödenen her türlü hizmet komisyonu ve benzeri giderler | D41: A2F01 | E41: =IFERROR(INDEX('QAR Kodları'!$B:$B,MATCH(D41,'QAR Kodları'!$A:$A,0)),"KOD BULUNAMADI") -> Receipts on account of financial intermediation except investment banking-bank charges, collection charges,lc charges, cancellation of forward | F41: Yakın | G41: Yurt içi yerleşikten alınan finansal hizmet; yurt dışına ödeniyorsa. | H41: 23) Bankacılık ve finansal hizmetlerle ilgili Ücret, masraf, komisyon ödemeleri
A42: =B42&"-"&D42 -> 5763-A2F02 | B42: 5763 | C42: Yurtiçinde yerleşik kişilerden finansal türev işlemleri ile ilgili alınan aracılık hizmetleri nedeniyle ödenen her türlü hizmet komisyonu ve benzeri giderler | D42: A2F02 | E42: =IFERROR(INDEX('QAR Kodları'!$B:$B,MATCH(D42,'QAR Kodları'!$A:$A,0)),"KOD BULUNAMADI") -> Receipts on account of investment banking services-brokerage, under writing commission etc | F42: Yakın | G42: Yurt içi yerleşikten türev aracılık hizmeti; yurt dışına ödeniyorsa. | H42: 23) Bankacılık ve finansal hizmetlerle ilgili Ücret, masraf, komisyon ödemeleri
A43: =B43&"-"&D43 -> 5770-A2R01 | B43: 5770 | C43: İmtiyaz ve ticari marka lisans giderleri | D43: A2R01 | E43: =IFERROR(INDEX('QAR Kodları'!$B:$B,MATCH(D43,'QAR Kodları'!$A:$A,0)),"KOD BULUNAMADI") -> Receipts on account of franchises services-use of patents, copy right trade marks, industrial processes, franchises etc. | F43: Tam | G43: İmtiyaz (franchise) ve ticari marka lisansı. | H43: 37) Hukuki danışmanlık, mahkeme, tazminat, bröve, marka tescil, üyelik/aidat işlemleri
A44: =B44&"-"&D44 -> 5771-A2R01 | B44: 5771 | C44: Telif, patent ve benzeri haklar nedeniyle ödenen bedeller | D44: A2R01 | E44: =IFERROR(INDEX('QAR Kodları'!$B:$B,MATCH(D44,'QAR Kodları'!$A:$A,0)),"KOD BULUNAMADI") -> Receipts on account of franchises services-use of patents, copy right trade marks, industrial processes, franchises etc. | F44: Tam | G44: Telif, patent ve benzeri hak bedeli. | H44: 28) Ticaret ve endüstri hizmetleri
A45: =B45&"-"&D45 -> 5772-A2R01 | B45: 5772 | C45: Araştırma ve geliştirme sonuçlarının kullanımına ilişkin lisans giderleri | D45: A2R01 | E45: =IFERROR(INDEX('QAR Kodları'!$B:$B,MATCH(D45,'QAR Kodları'!$A:$A,0)),"KOD BULUNAMADI") -> Receipts on account of franchises services-use of patents, copy right trade marks, industrial processes, franchises etc. | F45: Yakın | G45: Ar-Ge sonuçları kullanım lisansı. | H45: 28) Ticaret ve endüstri hizmetleri
A46: =B46&"-"&D46 -> 5773-A2R02 | B46: 5773 | C46: Bilgisayar yazılımlarının çoğaltılması ve/veya dağıtılmasına ilişkin lisans giderleri (Yazılımların toptan veya perakende alımı bilgisayar yazılım hizmetleri kodu altında gösterilecektir.) | D46: A2R02 | E46: =IFERROR(INDEX('QAR Kodları'!$B:$B,MATCH(D46,'QAR Kodları'!$A:$A,0)),"KOD BULUNAMADI") -> Receipts for use through licensing arrangements of produced originals or prototypes (such as manuscripts and films) | F46: Tam | G46: Orijinal/prototiplerin çoğaltma-dağıtım lisansı. | H46: 28) Ticaret ve endüstri hizmetleri
A47: =B47&"-"&D47 -> 5774-A2R02 | B47: 5774 | C47: Görsel-işitsel (audio-visual) ve ilgili ürünlerin çoğaltılması ve/veya dağıtılmasına ilişkin lisans giderleri | D47: A2R02 | E47: =IFERROR(INDEX('QAR Kodları'!$B:$B,MATCH(D47,'QAR Kodları'!$A:$A,0)),"KOD BULUNAMADI") -> Receipts for use through licensing arrangements of produced originals or prototypes (such as manuscripts and films) | F47: Tam | G47: Orijinal/prototiplerin çoğaltma-dağıtım lisansı. | H47: 28) Ticaret ve endüstri hizmetleri
A48: =B48&"-"&D48 -> 5775-A2R02 | B48: 5775 | C48: Görsel-işitsel (audio-visual) ve ilgili ürünler dışındaki ürünlerin çoğaltılması ve/veya dağıtılmasına ilişkin lisans giderleri | D48: A2R02 | E48: =IFERROR(INDEX('QAR Kodları'!$B:$B,MATCH(D48,'QAR Kodları'!$A:$A,0)),"KOD BULUNAMADI") -> Receipts for use through licensing arrangements of produced originals or prototypes (such as manuscripts and films) | F48: Tam | G48: Orijinal/prototiplerin çoğaltma-dağıtım lisansı. | H48: 28) Ticaret ve endüstri hizmetleri
A49: =B49&"-"&D49 -> 5780-A2K03 | B49: 5780 | C49: Telekomünikasyon hizmetleri: Yurtdışında yerleşik kişilerden sağlanan ses,görüntü, veri ve diğer bilgilerin telefon, teleks, telgraf, radyo ve televizyon uydusu kablo, elektronik posta vb. ile iletilmesi gibi hizmetler nedeniyle ödenen bedeller (Taşınan bilgilerin bedeli hariç tutulacaktır. İş ağı hizmetleri, telekonferans ve destek hizmetleri, mobil telekomünikasyon hizmetleri, internet altyapı hizmetleri, internet erişimi sağlanması dahil çevrimiçi erişim hizmetleri bu kod altında bildirilecektir) | D49: A2K03 | E49: =IFERROR(INDEX('QAR Kodları'!$B:$B,MATCH(D49,'QAR Kodları'!$A:$A,0)),"KOD BULUNAMADI") -> Receipts on account of settlement of claims for telecommunication services | F49: Tam | H49: 42) Telekomünikasyon Hizmetleri
A50: =B50&"-"&D50 -> 5781-A2E02 | B50: 5781 | C50: Bilgisayar yazılım hizmetleri: Yurtiçinde yerleşik kişiler için yazılım geliştirilmesi ve ilgili kullanım lisansları, yazılım sistemleri ve uygulamaları için orijinallerin (asılların) ve mülkiyet haklarının alımı vb. gibi yazılım hizmetleri nedeniyle ödenen bedeller | D50: A2E02 | E50: =IFERROR(INDEX('QAR Kodları'!$B:$B,MATCH(D50,'QAR Kodları'!$A:$A,0)),"KOD BULUNAMADI") -> Receipts on account of software implementation | F50: Tam | H50: 43) Bilgisayar ve Bilgi Hizmetleri
A51: =B51&"-"&D51 -> 5782-A2E04 | B51: 5782 | C51: Diğer bilgisayar hizmetleri: Yurtdışında yerleşik kişilerden bilgi işlemle ilgili olarak alınan danışmanlık, bakım, onarım sistem programlaması ve tasarımı hizmetleri (web sitesi tasarım ve kurulum hizmetleri dahil) ile veri kurtarma, veri işleme gibi bilgisayar donanım ve yazılım hizmetleri nedeniyle ödenen bedeller | D51: A2E04 | E51: =IFERROR(INDEX('QAR Kodları'!$B:$B,MATCH(D51,'QAR Kodları'!$A:$A,0)),"KOD BULUNAMADI") -> Receipts on account of repair and maintenance of computer and software | F51: Yakın | G51: Bakım/onarım. Danışmanlık ağırlıklıysa A2E01. | H51: 43) Bilgisayar ve Bilgi Hizmetleri
A52: =B52&"-"&D52 -> 5783-A2E05 | B52: 5783 | C52: Haber ajansı hizmetleri: Yurtdışında yerleşik medya kuruluşlarından haber, fotoğraf ve makale sağlanması dolayısıyla ödenen bedeller | D52: A2E05 | E52: =IFERROR(INDEX('QAR Kodları'!$B:$B,MATCH(D52,'QAR Kodları'!$A:$A,0)),"KOD BULUNAMADI") -> Receipts on account of provision of news agency services | F52: Tam | H52: 43) Bilgisayar ve Bilgi Hizmetleri
A53: =B53&"-"&D53 -> 5784-A2E06 | B53: 5784 | C53: Diğer bilgi hizmetleri: Yurtdışında yerleşik kişilerden alınan veri tabanı, veri saklama, veri dağıtım ve internet tarama hizmetleri ile gazete ve süreli yayınlara, posta, elektronik dağıtım veya diğer yollarla toplu olmayan doğrudan abonelikler nedeniyle ödenen bedeller | D53: A2E06 | E53: =IFERROR(INDEX('QAR Kodları'!$B:$B,MATCH(D53,'QAR Kodları'!$A:$A,0)),"KOD BULUNAMADI") -> Receipts on account of other information services-subscription to newspapers, periodicals etc. | F53: Yakın | G53: Abonelik/bilgi hizmeti. Veri tabanı/veri işleme ise A2E03. | H53: 43) Bilgisayar ve Bilgi Hizmetleri
A54: =B54&"-"&D54 -> 5790-A2J08 | B54: 5790 | C54: Araştırma geliştirme hizmetleri (Araştırma ve geliştirme faaliyetleri sonucu ortaya çıkan patent gibi ilgili fikri mülkiyet haklarının alımı nedeniyle ödenen bedeller dahil) | D54: A2J08 | E54: =IFERROR(INDEX('QAR Kodları'!$B:$B,MATCH(D54,'QAR Kodları'!$A:$A,0)),"KOD BULUNAMADI") -> Receipts towards research & development services | F54: Tam | H54: 28) Ticaret ve endüstri hizmetleri
...

Sheet QAR Kodları
A1: QAR PoP Kodu | B1: Purpose of Payment Narration (EN) | C1: Eşleşen İst. Kodu Sayısı
A2: A1A01 | B2: Value of export bills negotiated/purchased/discounted etc | C2: =COUNTIF(Eşleştirme!$D$2:$D$282,A2) -> 3
A3: A1A02 | B3: Realization of export bills (in respect of goods) sent on collection (full invoice value) | C3: =COUNTIF(Eşleştirme!$D$2:$D$282,A3) -> 1
A4: A1A03 | B4: Advance receipts against export contracts (export of goods only) | C4: =COUNTIF(Eşleştirme!$D$2:$D$282,A4) -> 1
A5: A2A04 | B5: Freight on exports-shipping companies | C5: =COUNTIF(Eşleştirme!$D$2:$D$282,A5) -> 3
A6: A2A10 | B6: Freight on exports-airlines companies | C6: =COUNTIF(Eşleştirme!$D$2:$D$282,A6) -> 3
A7: A2A01 | B7: Inward remittance on account of surplus freight/passenger fare by Qatari shipping companies operating abroad | C7: =COUNTIF(Eşleştirme!$D$2:$D$282,A7) -> 1
A8: A2A02 | B8: Operating expenses of foreign shipping companies operating in Qatar | C8: =COUNTIF(Eşleştirme!$D$2:$D$282,A8) -> 0
A9: A2A05 | B9: Receipt towards operational leasing (with crew) shipping companies | C9: =COUNTIF(Eşleştirme!$D$2:$D$282,A9) -> 0
A10: A2A07 | B10: Inward remittance of surplus freight/passenger fare by Qatari airlines companies operating abroad | C10: =COUNTIF(Eşleştirme!$D$2:$D$282,A10) -> 1
A11: A2A08 | B11: Receipts on account of operating expenses of foreign airlines companies operating in Qatar | C11: =COUNTIF(Eşleştirme!$D$2:$D$282,A11) -> 0
A12: A2A11 | B12: Receipts towards operational leasing (with crew) airlines companies | C12: =COUNTIF(Eşleştirme!$D$2:$D$282,A12) -> 0
A13: A2A13 | B13: Receipts towards other transportation services (stevedoring demurrage port handling charges etc | C13: =COUNTIF(Eşleştirme!$D$2:$D$282,A13) -> 14
... A86: A7C03 | B86: Receipts by residents from residents | C86: =COUNTIF(Eşleştirme!$D$2:$D$282,A86) -> 0
A88: Kaynak: Qatar Central Bank 2024 (kullanıcının paylaştığı QAR-Purpose-Codes.pdf). PDF'te kesik görünen açıklamalar olduğu gibi aktarılmıştır.
